<?xml version="1.0" ?>
<!-- =================================================================================== -->
<!-- |    This document was autogenerated by xacro from /root/catkin_ws/src/sim_device/thesis/urdf/lf06402.urdf.xacro | -->
<!-- |    EDITING THIS FILE BY HAND IS NOT RECOMMENDED                                 | -->
<!-- =================================================================================== -->
<robot name="lf064" xmlns:xacro="http://www.ros.org/wiki/xacro">
  <material name="Black">
    <color rgba="0.0 0.0 0.0 1.0"/>
  </material>
  <material name="Blue">
    <color rgba="0.0 0.0 0.8 1.0"/>
  </material>
  <material name="Green">
    <color rgba="0.0 0.8 0.0 1.0"/>
  </material>
  <material name="Grey">
    <color rgba="0.4 0.4 0.4 1.0"/>
  </material>
  <material name="Orange">
    <color rgba="1.0 0.423529411765 0.0392156862745 1.0"/>
  </material>
  <material name="Brown">
    <color rgba="0.870588235294 0.811764705882 0.764705882353 1.0"/>
  </material>
  <material name="Red">
    <color rgba="0.8 0.0 0.0 1.0"/>
  </material>
  <material name="White">
    <color rgba="1.0 1.0 1.0 1.0"/>
  </material>
  <!-- Fix to world just for testing -->
  <link name="world"/>
  <joint name="joint_lf06402" type="floating">
    <origin rpy="0 0 0" xyz="0 0 0"/>
    <parent link="world"/>
    <child link="link_lf06402"/>
  </joint>
  <!-- LINK LF064XX -->
  <link name="link_lf06402">
    <inertial>
      <mass value="0.00796"/>
      <origin xyz="0 0 0.018"/>
      <inertia ixx="0.000000716" ixy="0.0" ixz="0.0" iyy="0.000000716" iyz="0.0" izz="0.0000001144"/>
    </inertial>
    <visual>
      <origin rpy="0 0 0" xyz="0 0 0"/>
      <geometry>
        <mesh filename="file:///root/exchange/tempData/meshes/lf064-02.dae" scale="0.001 0.001 0.001"/>
      </geometry>
      <material name="grey">
        <color rgba="0.5 0.5 0.5 1"/>
      </material>
    </visual>
    <collision>
      <origin rpy="0 0 0" xyz="0 0 0"/>
      <geometry>
        <mesh filename="file:///root/exchange/tempData/meshes/lf064-02.dae" scale="0.001 0.001 0.001"/>
        <!--box size="0.8 0.8 1"/-->
      </geometry>
    </collision>
  </link>
  <gazebo reference="$link_lf06402">
    <material>Gazebo/Grey</material>
    <turnGravityOff>false</turnGravityOff>
    <mu1>0.6</mu1>
    <mu2>0.4</mu2>
  </gazebo>
  <gazebo>
    <plugin filename="libgazebo_ros_control.so" name="gazebo_ros_control">
      <robotNamespace>/lf06402</robotNamespace>
    </plugin>
  </gazebo>
</robot>

